<?xml version="1.0" encoding="utf-8"?>
<!-- =================================================================================== -->
<!-- |    This document was autogenerated by xacro from minibot.urdf.xacro             | -->
<!-- |    EDITING THIS FILE BY HAND IS NOT RECOMMENDED                                 | -->
<!-- =================================================================================== -->
<robot name="minibot">
  <link name="base_link">
    <visual>
      <origin rpy="0 0 0" xyz="0.0 0 0.0"/>
      <material name="body">
        <color rgba="0.905882352941 0.823529411765 0.250980392157 1.0"/>
      </material>
      <geometry>
        <mesh filename="package://minibot_moveit_config/config/stl/base.stl"/>
      </geometry>
    </visual>
    <collision>
      <geometry>
        <mesh filename="package://minibot_moveit_config/config/stl/base_collision.stl"/>
      </geometry>
    </collision>
  </link>
  <joint name="base_joint" type="revolute">
    <origin rpy="0.0 0 0.0" xyz="0 0 0.1005"/>
    <parent link="base_link"/>
    <child link="shoulder_link"/>
    <axis xyz="0 0 1"/>
    <limit effort="10.0" lower="-2.35619449019" upper="2.35619449019" velocity="1.57079632679"/>
    <safety_controller k_position="100.0" k_velocity="40.0" soft_lower_limit="-2.26892802759" soft_upper_limit="2.26892802759"/>
  </joint>
  <link name="shoulder_link">
    <visual>
      <origin rpy="0.0 -1.57079632679 -1.57079632679" xyz="0 0 0"/>
      <material name="body">
        <color rgba="0.905882352941 0.823529411765 0.250980392157 1.0"/>
      </material>
      <geometry>
        <mesh filename="package://minibot_moveit_config/config/stl/shoulder.stl"/>
      </geometry>
    </visual>
    <collision>
      <geometry>
        <mesh filename="package://minibot_moveit_config/config/stl/shoulder_collision.stl"/>
      </geometry>
    </collision>
  </link>
  <joint name="shoulder_joint" type="revolute">
    <origin rpy="0.0 0 0" xyz="0 0 0.0745"/>
    <parent link="shoulder_link"/>
    <child link="upperarm_link"/>
    <axis xyz="0 1 0"/>
    <limit effort="20" lower="-1.57079632679" upper="1.83259571459" velocity="2.09439510239"/>
    <safety_controller k_position="100.0" k_velocity="40.0" soft_lower_limit="-3.33794219444" soft_upper_limit="1.74532925199"/>
  </joint>
  <link name="upperarm_link">
    <visual>
      <origin rpy="0.0 -1.57079632679 1.57079632679" xyz="0 0 0"/>
      <material name="body">
        <color rgba="0.905882352941 0.823529411765 0.250980392157 1.0"/>
      </material>
      <geometry>
        <mesh filename="package://minibot_moveit_config/config/stl/upperarm.stl"/>
      </geometry>
    </visual>
    <collision>
      <geometry>
        <mesh filename="package://minibot_moveit_config/config/stl/upperarm_collision.stl"/>
      </geometry>
    </collision>
  </link>
  <!-- measured in CAD/upperarm.ipt -->
  <joint name="upperarm_joint" type="revolute">
    <origin rpy="0.0 0.349065850399 0" xyz="0.027362 0 0.105175"/>
    <parent link="upperarm_link"/>
    <child link="elbow_link"/>
    <axis xyz="0 1 0"/>
    <limit effort="20" lower="-2.00712863979" upper="2.00712863979" velocity="1.57079632679"/>
    <safety_controller k_position="100.0" k_velocity="40.0" soft_lower_limit="-1.91986217719" soft_upper_limit="1.91986217719"/>
  </joint>
  <link name="elbow_link">
    <visual>
      <origin rpy="-1.57079632679 -1.57079632679 0.0" xyz="0 0 0"/>
      <material name="body">
        <color rgba="0.905882352941 0.823529411765 0.250980392157 1.0"/>
      </material>
      <geometry>
        <mesh filename="package://minibot_moveit_config/config/stl/elbow.stl"/>
      </geometry>
    </visual>
    <collision>
      <geometry>
        <mesh filename="package://minibot_moveit_config/config/stl/elbow_collision.stl"/>
      </geometry>
    </collision>
  </link>
  <!-- measured in CAD/elbow.ipt -->
  <joint name="elbow_joint" type="revolute">
    <origin rpy="0.0 0.401425727959 0" xyz="0.052749 0 0.159268"/>
    <parent link="elbow_link"/>
    <child link="forearm_link"/>
    <axis xyz="0 0 1"/>
    <limit effort="15" lower="-3.12413936107" upper="3.12413936107" velocity="2.09439510239"/>
    <safety_controller k_position="100.0" k_velocity="40.0" soft_lower_limit="-2.96705972839" soft_upper_limit="2.96705972839"/>
  </joint>
  <link name="forearm_link">
    <visual>
      <origin rpy="-1.57079632679 -1.57079632679 0" xyz="0 0 0"/>
      <material name="body">
        <color rgba="0.905882352941 0.823529411765 0.250980392157 1.0"/>
      </material>
      <geometry>
        <mesh filename="package://minibot_moveit_config/config/stl/forearm.stl"/>
      </geometry>
    </visual>
    <collision>
      <geometry>
        <mesh filename="package://minibot_moveit_config/config/stl/forearm_collision.stl"/>
      </geometry>
    </collision>
  </link>
  <joint name="forearm_joint" type="revolute">
    <origin rpy="0.0 0.0 0" xyz="0.0 0 0.0"/>
    <parent link="forearm_link"/>
    <child link="wrist_link"/>
    <axis xyz="0 1 0"/>
    <limit effort="5" lower="-2.26892802759" upper="1.95476876223" velocity="1.57079632679"/>
    <safety_controller k_position="100.0" k_velocity="40.0" soft_lower_limit="-2.18166156499" soft_upper_limit="1.86750229963"/>
  </joint>
  <link name="wrist_link">
    <visual>
      <origin rpy="0 3.14159265359 1.57079632679" xyz="0 0 0"/>
      <material name="body">
        <color rgba="0.905882352941 0.823529411765 0.250980392157 1.0"/>
      </material>
      <geometry>
        <mesh filename="package://minibot_moveit_config/config/stl/wrist.stl"/>
      </geometry>
    </visual>
  </link>
  <joint name="wrist_joint" type="revolute">
    <origin rpy="0.0 0.174532925199 0" xyz="0.01046 0 0.05842"/>
    <parent link="wrist_link"/>
    <child link="flange_link"/>
    <axis xyz="0 0 1"/>
    <limit effort="5" lower="-3.12413936107" upper="3.12413936107" velocity="3.14159265359"/>
    <safety_controller k_position="100.0" k_velocity="40.0" soft_lower_limit="-2.96705972839" soft_upper_limit="2.96705972839"/>
  </joint>
  <!--  ###### -->
  <!--  flange -->
  <!--  ###### -->
  <link name="flange_link">
  </link>
  <joint name="flange_joint" type="fixed">
    <origin rpy="0 0 0" xyz="0 0 0"/>
    <parent link="flange_link"/>
    <child link="palm_link"/>
  </joint>
  <!--  ####################### -->
  <!--  tool centre point tool0 -->
  <!--  ####################### -->
  <joint name="tool0_joint" type="fixed">
    <origin rpy="0 0 0" xyz="0 0 0.0"/>
    <parent link="flange_link"/>
    <child link="tool0_link"/>
  </joint>
  <link name="tool0_link">
  </link>
  <!--  ############ -->
  <!--  minibot palm -->
  <!--  +########### -->
  <link name="palm_link">
    <visual>
      3.12413936107
          
      <origin rpy="0 0 1.57079632679" xyz="0 0 0.042"/>
      <material name="palm">
        <color rgba="0.839215686275 0.764705882353 0.23137254902 1.0"/>
      </material>
      <geometry>
        <mesh filename="package://minibot_moveit_config/config/stl/palm.stl"/>
      </geometry>
    </visual>
    <collision>
      <geometry>
        <mesh filename="package://minibot_moveit_config/config/stl/palm_collision.stl"/>
      </geometry>
    </collision>
  </link>
  <joint name="knuckle_joint" type="revolute">
    <origin rpy="0 0 0" xyz="0 0 0"/>
    <parent link="flange_link"/>
    <child link="knuckle_link"/>
    <axis xyz="0 0 1"/>
    <limit effort="5.0" lower="0" upper="1.0471975512" velocity="3.14159265359"/>
  </joint>
  <link name="knuckle_link">
  </link>
  <joint name="palm_left_joint" type="continuous">
    <origin rpy="0 0 0" xyz="0.010392 -0.006 0"/>
    <parent link="flange_link"/>
    <child link="knuckle_left_link"/>
    <axis xyz="0 0 1"/>
    <mimic joint="knuckle_joint" multiplier="1"/>
  </joint>
  <link name="knuckle_left_link">
    <visual>
      <origin rpy="0 3.14159265359 1.57079632679" xyz="-0.010392 0.006 0.0425"/>
      <material name="palm">
        <color rgba="0.839215686275 0.764705882353 0.23137254902 1.0"/>
      </material>
      <geometry>
        <mesh filename="package://minibot_moveit_config/config/stl/knuckle_left.stl"/>
      </geometry>
    </visual>
  </link>
  <joint name="palm_right_joint" type="continuous">
    <origin rpy="0 0 0" xyz="0.010392 0.006 0"/>
    <parent link="flange_link"/>
    <child link="knuckle_right_link"/>
    <axis xyz="0 0 1"/>
    <mimic joint="knuckle_joint" multiplier="-1"/>
  </joint>
  <link name="knuckle_right_link">
    <visual>
      <origin rpy="0 3.14159265359 1.57079632679" xyz="-0.010392 -0.006 0.0425"/>
      <material name="palm">
        <color rgba="0.839215686275 0.764705882353 0.23137254902 1.0"/>
      </material>
      <geometry>
        <mesh filename="package://minibot_moveit_config/config/stl/knuckle_right.stl"/>
      </geometry>
    </visual>
    <!-- no collision objects, knuckles are excluded from collision checking -->
  </link>
  <!--  ############ -->
  <!--  minibot hand -->
  <!--  +########### -->
  <!-- heigth of centre finger relativey to palm centre -->
  <!-- measured from CAD Model "Gripper.iam" -->
  <joint name="finger_joint" type="revolute">
    <origin rpy="0 0 0" xyz="0 0 0"/>
    <parent link="flange_link"/>
    <child link="finger_link"/>
    <axis xyz="0 1 0"/>
    <limit effort="50.0" lower="-0.174532925199" upper="1.0471975512" velocity="31.4159265359"/>
  </joint>
  <link name="finger_link">
  </link>
  <joint name="finger_centre_joint" type="continuous">
    <origin rpy="0 0 0" xyz="-0.027392 0 0.0625"/>
    <parent link="flange_link"/>
    <child link="finger_centre_link"/>
    <axis xyz="0 1 0"/>
    <mimic joint="finger_joint" multiplier="-1"/>
  </joint>
  <link name="finger_centre_link">
    <visual>
      <origin rpy="1.57079632679 0 3.14159265359" xyz="0 0 0"/>
      <material name="finger">
        <color rgba="0.62 0.25 0.25 1.0"/>
      </material>
      <geometry>
        <mesh filename="package://minibot_moveit_config/config/stl/finger.stl"/>
      </geometry>
    </visual>
    <collision>
      <geometry>
        <mesh filename="package://minibot_moveit_config/config/stl/finger_collision.stl"/>
      </geometry>
    </collision>
  </link>
  <joint name="finger_left_joint" type="continuous">
    <origin rpy="0 0 -1.0471975512" xyz="0.003108 -0.017383 0.0625"/>
    <parent link="knuckle_left_link"/>
    <child link="finger_left_link"/>
    <axis xyz="0 1 0"/>
    <mimic joint="finger_joint" multiplier="1"/>
  </joint>
  <link name="finger_left_link">
    <visual>
      <origin rpy="1.57079632679 0 0" xyz="0.0 0 0"/>
      <material name="finger">
        <color rgba="0.62 0.25 0.25 1.0"/>
      </material>
      <geometry>
        <mesh filename="package://minibot_moveit_config/config/stl/finger.stl"/>
      </geometry>
    </visual>
    <collision>
      <geometry>
        <mesh filename="package://minibot_moveit_config/config/stl/finger_collision.stl"/>
      </geometry>
    </collision>
  </link>
  <joint name="finger_right_joint" type="continuous">
    <origin rpy="0 0 1.0471975512" xyz="0.003108 0.017383 0.0625"/>
    <parent link="knuckle_right_link"/>
    <child link="finger_right_link"/>
    <axis xyz="0 1 0"/>
    <mimic joint="finger_joint" multiplier="1"/>
  </joint>
  <link name="finger_right_link">
    <visual>
      <origin rpy="1.57079632679 0 0" xyz="0.0 0 0"/>
      <material name="finger">
        <color rgba="0.62 0.25 0.25 1.0"/>
      </material>
      <geometry>
        <mesh filename="package://minibot_moveit_config/config/stl/finger.stl"/>
      </geometry>
    </visual>
    <collision>
      <geometry>
        <mesh filename="package://minibot_moveit_config/config/stl/finger_collision.stl"/>
      </geometry>
    </collision>
  </link>
</robot>
